Workbook

Sheet Notes_Old
B1: NOTES:
A2: 1 | B2: Version | C2: 2
A3: 2 | B3: Date of version | C3: 44743
A4: 3 | B4: Report file name: Please replace the MMM-YYYY_XXXXXXX in the report filename (MLAG-MRT_V1_MMM-YYYY_XXXX) with first 3 letters of the month of the reporting date, the year and last 7 characters of the member's MLAG ID. E.g. MLAG-MRT_Dec-2014_0000001
A5: 4 | B5: Please select 'Report Code' from the drop down list in the first ('P&L') sheet and they will be populated on the other sheets. Report Code'MLAG-PR-UA' is to be selected for unaudited (UA) performance report (PR), which are currently expected to have quarterly reporting frequency. Report code 'MLAG-PR-A' is for reports that are based on audited figures and these are expected to be submitted annually. Also, please provide the other head information on the first ('P&L') sheet and they will be populated on the other sheets.
A6: 5 | B6: Reporting date: enter as Month and year ending the reporting period (e.g 12/2014 for quarter ending December 2014)
A7: 6 | B7: Reporting Period: enter the months and year covered in the reporting period (e.g October -December, 2015 for the October to December 2015 quarter )
A8: 7 | B8: The 'Regional Breakdown' sheet should be completed before the 'Portfolio Report' sheet and the 'Outreach & Social Performance' sheet so that data entered in the former will automatically populate relevant sections of the latter.
A9: 8 | B9: "Error" at the top of the Balance Sheet indicates that the Total Assets are not equal to Total Liabilities and Capital and there is need for checking and correction before submission.
A10: 9 | B10: Gross Loan Portfolio in the Balance Sheet must be equal to the Gross Loans Outstanding in the Portfolio Report, otherwise "Error" is indicated and correction is required.
A11: 10 | B11: Loan "Impairment Loss Allowance" (Loan loss reserves) in the Balnace Sheet (line 2.5) is linked to the Portfolio Report (line 3.15) - Total Actual Provisions made. Please input the actual loan loss provisions as at the reporting date in that section of the Portfolio Report and it will automatically reflect in the Balance sheet.
B13: Unique Code for File
B14: =C2&"-"&'Profit & Loss Statement'!C9&"-"&'Profit & Loss Statement'!C5&"-"&'Profit & Loss Statement'!C7 -> 2---
B16: Version Number
B17: =C2 -> 2

Sheet Errors Summary Sheet
A1: Doc Version | B1: 8
A2: Error Count Dashboard | C2: Error Description | F2: Cover Sheet | G2: Profit & Loss Statement | H2: Balance Sheet | I2: Portfolio Report | J2: Outreach & Social Performance | K2: Regional Breakdown | L2: Ratios
A3: Cover Sheet | B3: ='Cover Sheet'!E1 -> 6 | C3: =IF(ISTEXT(F4),F4)&IF(ISTEXT(F5),F5)&IF(ISTEXT(F6),F6)&IF(ISTEXT(F7),F7)&IF(ISTEXT(F8),F8)&IF(ISTEXT(F9),F9)&IF(ISTEXT(F10),F10) -> Member Name Not Entered!; Member Code Not Entered!; Year not entered!; Reporting Quarter Not Entered!; Reporting Date not populated!; Region not populated!;
A4: Profit & Loss Statement | B4: ='Profit & Loss Statement'!E1 -> 6 | C4: =IF(ISTEXT(G4),G4)&IF(ISTEXT(G5),G5)&IF(ISTEXT(G6),G6)&IF(ISTEXT(G7),G7)&IF(ISTEXT(G8),G8)&IF(ISTEXT(G9),G9)&IF(ISTEXT(G10),G10) -> Member Name Not Entered!; Member Code Not Entered!; Reporting Period Not Entered!; Reporting Date Not Entered!; Year Not Entered!; Region not populated!; | F4: =IF('Cover Sheet'!D4=1, "Member Name Not Entered!; ", "") -> Member Name Not Entered!; | G4: =IF('Profit & Loss Statement'!D4=1, "Member Name Not Entered!; ", "") -> Member Name Not Entered!; | H4: =IF('Balance Sheet'!D4=1, "Member Name Not Entered!; ", "") -> Member Name Not Entered!; | I4: =IF('Portfolio Report'!D4=1, "Member Name Not Entered!; ", "") -> Member Name Not Entered!; | J4: =IF('Outreach & Social Performance'!D4=1, "Member Name Not Entered!; ", "") -> Member Name Not Entered!; | K4: =IF('Regional Breakdown '!D4=1, "Member Name Not Entered!; ", "") -> Member Name Not Entered!;
A5: Balance Sheet | B5: ='Balance Sheet'!E1 -> 11 | C5: =IF(ISTEXT(H4),H4)&IF(ISTEXT(H5),H5)&IF(ISTEXT(H6),H6)&IF(ISTEXT(H7),H7)&IF(ISTEXT(H8),H8)&IF(ISTEXT(H9),H9)&IF(ISTEXT(H10),H10)&IF(ISTEXT(H11),H11)&IF(ISTEXT(H12),H12)&IF(ISTEXT(H13),H13)&IF(ISTEXT(H14),H14)&IF(ISTEXT(H15),H15)&IF(ISTEXT(H16),H16) -> Member Name Not Entered!; Member Code Not Entered!; Reporting Period Not Entered!; Reporting Date Not Entered!; Year Not Entered!; Cash on hand and Due from Bank cannot be empty!; Cash on hand and Due from Bank cannot be zero!; Gross Loan Portfolio cannot be empty!; Gross Loan Portfolio cannot be zero!; Region not populated!; Impairment Loss Allowance cannot be Empty!; | F5: =IF('Cover Sheet'!D5=1, "Member Code Not Entered!; ", "") -> Member Code Not Entered!; | G5: =IF('Profit & Loss Statement'!D5=1, "Member Code Not Entered!; ", "") -> Member Code Not Entered!; | H5: =IF('Balance Sheet'!D5=1, "Member Code Not Entered!; ", "") -> Member Code Not Entered!; | I5: =IF('Portfolio Report'!D5=1, "Member Code Not Entered!; ", "") -> Member Code Not Entered!; | J5: =IF('Outreach & Social Performance'!D5=1, "Member Code Not Entered!; ", "") -> Member Code Not Entered!; | K5: =IF('Regional Breakdown '!D5=1, "Member Code Not Entered!; ", "") -> Member Code Not Entered!;
A6: Portfolio Report | B6: ='Portfolio Report'!E1 -> 6 | C6: =IF(ISTEXT(I4),I4)&IF(ISTEXT(I5),I5)&IF(ISTEXT(I6),I6)&IF(ISTEXT(I7),I7)&IF(ISTEXT(I8),I8)&IF(ISTEXT(I9),I9)&IF(ISTEXT(I10),I10)&IF(ISTEXT(I11),I11)&IF(ISTEXT(I12),I12)&IF(ISTEXT(I13),I13) -> Member Name Not Entered!; Member Code Not Entered!; Reporting Period Not Entered!; Reporting Date Not Entered!; Year Not Entered!; Region not populated!; | F6: =IF('Cover Sheet'!D6=1, "Return Code Not Entered!; ", "") | G6: =IF('Profit & Loss Statement'!D6=1, "Return Code Not Entered!; ", "") | H6: =IF('Balance Sheet'!D6=1, "Return Code Not Entered!; ", "") | I6: =IF('Portfolio Report'!D6=1, "Return Code Not Entered!; ", "") | J6: =IF('Outreach & Social Performance'!D6=1, "Return Code Not Entered!; ", "") | K6: =IF('Regional Breakdown '!D6=1, "Return Code Not Entered!; ", "")
A7: Outreach & Social Performance | B7: ='Outreach & Social Performance'!E1 -> 6 | C7: =IF(ISTEXT(J4),J4)&IF(ISTEXT(J5),J5)&IF(ISTEXT(J6),J6)&IF(ISTEXT(J7),J7)&IF(ISTEXT(J8),J8)&IF(ISTEXT(J9),J9)&IF(ISTEXT(J10),J10) -> Member Name Not Entered!; Member Code Not Entered!; Reporting Period Not Entered!; Reporting Date Not Entered!; Year Not Entered!; Region not populated!; | F7: =IF('Cover Sheet'!D7=1, "Year not entered!; ","") -> Year not entered!; | G7: =IF('Profit & Loss Statement'!D7=1, "Reporting Period Not Entered!; ","") -> Reporting Period Not Entered!; | H7: =IF('Balance Sheet'!D7=1, "Reporting Period Not Entered!; ","") -> Reporting Period Not Entered!; | I7: =IF('Portfolio Report'!D7=1, "Reporting Period Not Entered!; ","") -> Reporting Period Not Entered!; | J7: =IF('Outreach & Social Performance'!D7=1, "Reporting Period Not Entered!; ","") -> Reporting Period Not Entered!; | K7: =IF('Regional Breakdown '!D7=1, "Reporting Period Not Entered!; ","") -> Reporting Period Not Entered!;
A8: Regional Breakdown | B8: ='Regional Breakdown '!E1 -> 6 | C8: =IF(ISTEXT(K4),K4)&IF(ISTEXT(K5),K5)&IF(ISTEXT(K6),K6)&IF(ISTEXT(K7),K7)&IF(ISTEXT(K8),K8)&IF(ISTEXT(K9),K9)&IF(ISTEXT(K10),K10)&IF(ISTEXT(K11),K11)&IF(ISTEXT(K12),K12)&IF(ISTEXT(K13),K13) -> Member Name Not Entered!; Member Code Not Entered!; Reporting Period Not Entered!; Reporting Date Not Entered!; Year Not Entered!; Region not populated!; | F8: =IF('Cover Sheet'!D8=1, "Reporting Quarter Not Entered!; ","") -> Reporting Quarter Not Entered!; | G8: =IF('Profit & Loss Statement'!D8=1, "Reporting Date Not Entered!; ","") -> Reporting Date Not Entered!; | H8: =IF('Balance Sheet'!D8=1, "Reporting Date Not Entered!; ","") -> Reporting Date Not Entered!; | I8: =IF('Portfolio Report'!D8=1, "Reporting Date Not Entered!; ","") -> Reporting Date Not Entered!; | J8: =IF('Outreach & Social Performance'!D8=1, "Reporting Date Not Entered!; ","") -> Reporting Date Not Entered!; | K8: =IF('Regional Breakdown '!D8=1, "Reporting Date Not Entered!; ","") -> Reporting Date Not Entered!;
A9: Ratios | B9: =Ratios!H1 -> 0 | C9: =IF(L4 = "","",L4)&IF(L5 = "","",L5)&IF(L6 = "","",L6)&IF(L7 = "","",L7)&IF(L8 = "","",L8)&IF(L9 = "","",L9) | F9: =IF('Cover Sheet'!D9=1, "Reporting Date not populated!; ","") -> Reporting Date not populated!; | G9: =IF('Profit & Loss Statement'!D9=1, "Year Not Entered!; ","") -> Year Not Entered!; | H9: =IF('Balance Sheet'!D9=1, "Year Not Entered!; ","") -> Year Not Entered!; | I9: =IF('Portfolio Report'!D9=1, "Year Not Entered!; ","") -> Year Not Entered!; | J9: =IF('Outreach & Social Performance'!D9=1, "Year Not Entered!; ","") -> Year Not Entered!; | K9: =IF('Regional Breakdown '!D9=1, "Year Not Entered!; ","") -> Year Not Entered!;
F10: =IF('Cover Sheet'!D10=1, "Region not populated!; ","") -> Region not populated!; | G10: =IF('Profit & Loss Statement'!D10=1, "Region not populated!; ","") -> Region not populated!; | H10: =IF('Balance Sheet'!D24<>'Balance Sheet'!D43, "Total Assets MUST be equal to Total Liabilities and Equity!; ","") | I10: =IF('Portfolio Report'!E13<>'Portfolio Report'!E27, "Total Gross Portfolio MUST be equal to Outstanding Loans!; ","") | J10: =IF('Outreach & Social Performance'!D10=1, "Region not populated!; ","") -> Region not populated!; | K10: =IF('Regional Breakdown '!D10=1, "Region not populated!; ","") -> Region not populated!;
H11: =IF('Balance Sheet'!D13="", "Cash on hand and Due from Bank cannot be empty!; ","") -> Cash on hand and Due from Bank cannot be empty!; | I11: =IF('Portfolio Report'!E13<>'Portfolio Report'!E51, "Total Gross Loan Outstanding MUST be equal to Outstanding Loans!; ","") | K11: =IF('Regional Breakdown '!D15<>'Regional Breakdown '!D28, "Number of Loans Outstanding MUST be equal to number of Total Gross Loans Outstanding!; ","")
A12: NOTES | H12: =IF('Balance Sheet'!D13=0, "Cash on hand and Due from Bank cannot be zero!; ","") -> Cash on hand and Due from Bank cannot be zero!; | I12: =IF('Portfolio Report'!D10=1, "Region not populated!; ","") -> Region not populated!; | K12: =IF('Regional Breakdown '!D15<>'Regional Breakdown '!D57, "Number of Loans Outstanding MUST be equal to number of Active Borrowers!; ","")
A13: 1 | B13: The above shows the total number of errors in your quarterly prudential report. | G13: MCAG-8-R-RB-OSP-PR-BS-PLS | H13: =IF('Balance Sheet'!D16="", "Gross Loan Portfolio cannot be empty!; ","") -> Gross Loan Portfolio cannot be empty!; | I13: =IF(ROUND('Portfolio Report'!G27,2)>ROUND('Portfolio Report'!H27,2), "Actual Provision should be greater or equal to Min. Required Provision!; ","") | K13: =IF('Regional Breakdown '!D28<>'Regional Breakdown '!D52, "Number of Total Gross Loans Outstanding MUST be the same!; ","")
A14: 2 | B14: The total number of Errors next to each line item should be zero (0) | H14: =IF('Balance Sheet'!D16=0, "Gross Loan Portfolio cannot be zero!; ","") -> Gross Loan Portfolio cannot be zero!;
A15: 3 | B15: Please ensure you submit the return to the Association only when number of errors is 0, otherwise it will be rejected by the system | H15: =IF('Balance Sheet'!D10=1, "Region not populated!; ","") -> Region not populated!;
H16: =IF('Balance Sheet'!D17=0,"Impairment Loss Allowance cannot be Empty!; ","") -> Impairment Loss Allowance cannot be Empty!;

Sheet Cover Sheet
A1: MICRO – CREDIT ASSOCIATION GHANA | E1: =SUM(D4:D10) -> 6 | F1: =IF(SUM(D4:D9)=0,"","Error!") -> Error! | J1: Q1 | K1: =TEXT(TODAY() - 365, "YYYY") -> 2021
A2: MEMBERS REPORTING TEMPLATE | J2: Q2 | K2: =TEXT(TODAY(), "YYYY") -> 2022
J3: Q3 | K3: =TEXT(TODAY() + 365, "YYYY") -> 2023
B4: MEMBER NAME: | D4: =IF(C4="",1,IF(ISTEXT(C4),0,1))+IF(OR(ISNUMBER(LEFT(C4)),LEFT(C4)=" "),1,0) -> 1 | J4: Q4
B5: MEMBER CODE: | D5: =IF(C5="",1,IF(ISTEXT(C5),0,1))+IF(OR(ISNUMBER(LEFT(C5)),LEFT(C5)=" "),1,0) -> 1
B6: RETURN CODE: | C6: MCAG-PR-UA | D6: =IF(C6="",1,IF(ISTEXT(C6),0,1)) -> 0
B7: YEAR | D7: =IF(C7="",1,0) -> 1
B8: REPORTING QUARTER | D8: =IF(C8="",1,IF(ISTEXT(C8),0,1)) -> 1
B9: REPORTING DATE | C9: =IF(SUM(C12:C13)=2, C11&" "&C14, "") | D9: =IF(C9="",1, 0) -> 1
B10: REGION | D10: =IF(C10="",1, 0) -> 1
C11: =IF(C8="Q1", "April", IF(C8="Q2", "July",IF(C8="Q3","October",IF(C8="Q4","January",""))))
C12: =IF(ISBLANK(C7), 0, 1) -> 0 | D12: Year
C13: =IF(ISBLANK(C8), 0,1) -> 0 | D13: Quarter
C14: =IF(C11="", "", IF(C11="January", C7+1, C7))
B18: ALL REGIONS
B19: Ahafo-AF
B20: Ashanti-AS
B21: Bono-BN
B22: Bono East-BE
B23: Central-CR
B24: Eastern-ER
B25: Greater Accra-GA
B26: North East-NE
B27: Northern-NR
B28: Oti-OT
B29: Savannah-SV
... B34: Western North-WN

Sheet Profit & Loss Statement
A1: MICRO – CREDIT ASSOCIATION GHANA | E1: =SUM(D4:D10) -> 6 | F1: =IF(SUM(D4:D9)=0,"","Error!") -> Error!
A2: MEMBERS REPORTING TEMPLATE
B4: MEMBER NAME: | C4: =IF('Cover Sheet'!C4="", "", 'Cover Sheet'!C4) | D4: =IF(C4="",1,IF(ISTEXT(C4),0,1))+IF(OR(ISNUMBER(LEFT(C4)),LEFT(C4)=" "),1,0) -> 1
B5: MEMBER CODE: | C5: =IF('Cover Sheet'!C5="", "", 'Cover Sheet'!C5) | D5: =IF(C5="",1,IF(ISTEXT(C5),0,1))+IF(OR(ISNUMBER(LEFT(C5)),LEFT(C5)=" "),1,0) -> 1
B6: RETURN CODE: | C6: =IF('Cover Sheet'!C6="", "", 'Cover Sheet'!C6) -> MCAG-PR-UA | D6: =IF(C6="",1,IF(ISTEXT(C6),0,1)) -> 0
B7: REPORTING PERIOD | C7: =IF('Cover Sheet'!C8="Q1", "January - March "&'Cover Sheet'!C7, IF('Cover Sheet'!C8="Q2", "April - June "&'Cover Sheet'!C7, IF('Cover Sheet'!C8="Q3", "July - September "&'Cover Sheet'!C7, IF('Cover Sheet'!C8="Q4", "October - December "&'Cover Sheet'!C7, "")))) | D7: =IF(C7="",1,IF(ISTEXT(C7),0,1)) -> 1
B8: REPORTING DATE | C8: ='Cover Sheet'!C9 | D8: =IF(C8="",1, 0) -> 1
B9: YEAR | C9: =IF('Cover Sheet'!C7="", "", 'Cover Sheet'!C7) | D9: =IF(C9="",1, 0) -> 1
B10: REGION | C10: =IF('Cover Sheet'!C10="", "", 'Cover Sheet'!C10) | D10: =IF(C10="",1, 0) -> 1
A11: 1.0. | B11: INCOME STATEMENT | D11: Data for the reporting quarter
B12: Indicator | C12: Explanation (Definition of Indicator) | D12: GHS
A13: 1.1 | B13: Interest on Loan Portfolio | C13: Interest earned on the loan portfolio actually received during the reporting period.
A14: 1.2 | B14: Fees and Commissions on Loan Portfolio | C14: Penalties, commissions, and other fees earned on the loan portfolio.
A15: 1.3 | B15: Interest from Investments | C15: Interest earned on financial assets other than the loan portfolio, such as interest-bearing deposits, certificates of deposit, and treasury obligations. This may also include recovery of interest on previously written off loans.
A16: 1.4 | B16: Other income from investments | C16: Dividend and other income and payments generated by financial assets other than the loan portfolio.
A17: 1.5 | B17: Other operating Revenue | C17: All other revenue from the provision of financial services, including transaction fees, premiums, membership fees, passbooks, and smartcards.
A18: 1.6 | B18: Total Operating Revenue | C18: Line (1.1+1.2+1.3+1.4+1.5) | D18: =SUM(D13:D17) -> 0
B19: Financial Expense
A20: 1.7 | B20: Interest on Client Investments | C20: Interest on all client investments held by the ML-MFI.
A21: 1.8 | B21: Fees expense on Client Investments | C21: Fees for acquiring funds from client investments for operations.
A22: 1.9 | B22: Interest on Borrowings | C22: Interest on all borrowings that fund the loan portfolio. This account does not include interest and fees on non-funding liabilities, such as mortgages or car loans.
A23: 1.10 | B23: Fees expense on Borrowings | C23: Fees for acquiring funds from borrowings for operations.
A24: 1.11 | B24: Other Financial expense | C24: Other financial expense related to financial services, including interest on non-funding liabilities, such as mortgages, and loans linked to fixed assets, such as vehicles.
A25: 1.12 | B25: Total Financial Expense | C25: Total financial expense from operations including interest, fees and charges on loans, deposits and other liabilities. | D25: =SUM(D20:D24) -> 0
A26: 1.13 | B26: Net Interest Income | C26: Interest income less interest expense from operations - Line (1.1+1.3) less (1.7+1.9) | D26: =(D13+D15)-(D20+D22) -> 0
A27: 1.14 | B27: Provision for Loan Impairment | C27: Also known as Gross Loan Loss Provision Expense, the non-cash expense calculated as a percentage of the value of the loan portfolio that is at risk of default.
A28: 1.15 | B28: Value of Loans Recovered | C28: Total value of principal recovered on all loans previously written off, entered as a NEGATIVE number. This includes principal on partially recovered loans and those recovered in full.
B29: Operating Expense
A30: 1.16 | B30: Personnel Expense | C30: Includes staff salaries, bonuses, and benefits, as well as employment taxes. It also includes the cost of employee recruitment and initial orientation. This excludes staff training cost.
A31: 1.17 | B31: Depreciation and Amortization Expense | C31: The non-cash expense that allocates the purchase cost of an MFI's fixed assets over their useful economic life. Amortization is used for other tangible assets, such as software.
A32: 1.18 | B32: Other Administrative Expense | C32: Non-financial expenses excluding personnel directly related to the provision of financial services or other services that form an integral part of an MFI's financial services' relationship with its clients. This includes staff training costs.
A33: 1.19 | B33: Total Operating Expense | C33: Sum(1.16+1.17+1.18) | D33: =SUM(D30:D32) -> 0
A34: 1.20 | B34: Net Operating Income | C34: Net earnings from financial services . Line (1.6-1.12)-(1.14+1.15)-1.19 | D34: =D18-D25-(D27+D28)-D33 -> 0
A35: 1.21 | B35: Non-Operating Revenue | C35: The net earnings from products and services not directly related to core microfinance (money lending) operations.
A36: 1.22 | B36: Non- operating expense | C36: All expenses not directly related to the core microfinance (money lending) operation, such as the cost of providing business development services or training, entered as a NEGATIVE number. This account also includes any exceptional losses and expenses.
A37: 1.23 | B37: Total Income Before Tax | C37: Line 1.20+(1.21+1.22) | D37: =D34+(D35+D36) -> 0
A38: 1.24 | B38: Tax | C38: Tax on profit
A39: 1.25 | B39: Net Income After Tax | C39: Line 1.23-1.24 | D39: =D37-D38 -> 0
B41: ADJUSTED P&L ITEMS
A42: 1.26 | B42: Adjusted Personnel Expense (GHS) | C42: Calculated as : Actual Personnel Expense +( Estimated Market Cost of Personnel – Actual Cost of Personnel) .
...

Sheet Balance Sheet
A1: ='Profit & Loss Statement'!A1:D1 -> MICRO – CREDIT ASSOCIATION GHANA | E1: =SUM(D4:D10) + IF(D43=D24,0,1) + IF(D13="",1,0) + IF(D13=0,1,0) + IF(D16="",1,0) + IF(D16=0,1,0) + IF(D17=0,1,0) -> 11 | F1: =IF(D43<>D24,"Error!", IF(SUM(D4:D9)>0, "Error!", "")) -> Error!
A2: ='Profit & Loss Statement'!A2:D2 -> MEMBERS REPORTING TEMPLATE
B4: MEMBER NAME: | C4: =IF('Profit & Loss Statement'!C4 = "", "", 'Profit & Loss Statement'!C4) | D4: =IF(C4= "",1,0) -> 1
B5: MEMBER CODE: | C5: =IF('Profit & Loss Statement'!C5 = "", "", 'Profit & Loss Statement'!C5) | D5: =IF(C5= "",1,0) -> 1
B6: RETURN CODE: | C6: =IF('Profit & Loss Statement'!C6 = "", "", 'Profit & Loss Statement'!C6) -> MCAG-PR-UA | D6: =IF(C6= "",1,0) -> 0
B7: REPORTING PERIOD | C7: =IF('Profit & Loss Statement'!C7 = "", "", 'Profit & Loss Statement'!C7) | D7: =IF(C7= "",1,0) -> 1
B8: REPORTING DATE | C8: =IF('Profit & Loss Statement'!C8 = "", "", 'Profit & Loss Statement'!C8) | D8: =IF(C8="",1, 0) -> 1
B9: YEAR | C9: ='Profit & Loss Statement'!C9 | D9: =IF(C9="",1, 0) -> 1
B10: REGION | C10: =IF('Cover Sheet'!C10="", "", 'Cover Sheet'!C10) | D10: =IF(C10="",1, 0) -> 1
A11: 2.0 | B11: BALANCE SHEET
B12: Assets | D12: GHS
A13: 2.1 | B13: Cash on hand and Due from Bank | C13: Cash and non-interest bearing bank balances and very short-dated (e.g. overnight) instruments with little or no interest. | E13: =IF(D13="","Error!", IF(D13=0, "Error!", "")) -> Error!
A14: 2.2 | B14: Short Term Investment- Treasury Bills | C14: Investments in Government paper (Treasury Bills) with not more than 12 months maturity.
A15: 2.3 | B15: Short Term Investments-Other | C15: Any financial assets other than treasury bills, acquired or incurred primarily for the purpose of selling or repurchasing in the near term; i.e., convertible to cash within 12 months. These may include certificates of deposit, including interest-bearing deposits and are often used in liquidity management.
A16: 2.4 | B16: Gross Loan Portfolio | C16: Outstanding principal for all outstanding client loans. This includes current, delinquent, and renegotiated loans, but not loans that have been written off. It does not include interest receivable. Loans to employees, board members, or others associated with the institution should be included. | E16: =IF(D16="","Error!", IF(D16=0, "Error!", "")) -> Error!
A17: 2.5 | B17: Impairment Loss Allowance | C17: Previously known as the loan loss allowance, the portion of the Gross Loan Portfolio that has been expensed (provisioned for) in anticipation of losses due to default. This item represents the cumulative value of the impairment losses on loans less the cumulative value of loans written off. Express this item as a contra asset account and state it as a negative number. (this figure should be negative) | D17: =-'Portfolio Report'!H27 -> 0 | E17: =IF(D17=0,"Error!","") -> Error!
A18: 2.6 | B18: Net Loan Portfolio | C18: Gross loan portfolio less impairment loss allowance (loan loss reserves or accumulated provision for loan losses) | D18: =D16+D17 -> 0
A19: 2.7 | B19: Accounts Receivable and other Assets | C19: Accounts receivable, notes receivables, and other receivables, net of any allowances for doubtful or uncollectible accounts. This includes all receivables other than client loan accounts, including interest receivable on non-funding liabilities such as mortgages.
A20: 2.8 | B20: Long term Investments | C20: Include investments that have a fixed maturity or payments that the MFI intents to hold to maturity. This item may include bonds or shares that the MFI plans to hold for 12 months or more or other financial assets available for sale but not considered loans, receivables, or Trade Investments.
A21: 2.9 | B21: Fixed Assets | C21: The cost or value of all physical property and property improvements, furniture, and equipment that the MFI currently uses.
A22: 2.10 | B22: Accumulated Depreciation and Amortization(this figure should be negative) | C22: The sum of all depreciation expenses for Fixed Assets and the amortization of other tangible assets that have not yet been retired and removed from the balance sheet. Accumulated depreciation represents the reduction in value of Fixed Assets corresponding to the assets' remaining useful life. This contra asset account is expressed as a negative number.
A23: 2.11 | B23: Net Fixed Assets | C23: Gross fixed assets less accumulated depreciation | D23: =D21+D22 -> 0
A24: 2.12 | B24: Total Assets | D24: =ROUND((D13+D14+D15+D18+D19+D20+D23),2) -> 0
B25: Liabilities
A26: 2.13 | B26: Security Deposit | C26: This includes compulsory or security cash deposits that are held by the MFI as a condition for a current or future loan or other service, such as cash collateral accounts or guarantee deposits.
A27: 2.14 | B27: Short term Borrowing | C27: The principal balance due within 12 months from the statement date for all funds received through loans, clients investments for fixed period or other contractual debt agreement. This includes loans, lines of credit, and overdraft facilities with outstanding balances, as well as the portion of long-term obligations payable within 12 months.
A28: 2.15 | B28: Long term borrowing | C28: The principal balance due in more than 12 months for all funds received through loans, clients investments for fixed period or other contractual agreement and all subordinated debt.
A29: 2.16 | B29: Total Borrowing | D29: =D27+D28 -> 0
A30: 2.17 | B30: Interest payable on funding liabilities | C30: Interest accrued on liability accounts that fund financial operations. It does not include borrowing for purchasing or improving real estate or other fixed assets such as vehicles.
A31: 2.18 | B31: Accounts Payable & Other Short-term Liabilities | C31: Other short-term liabilities due within 12 months, including tax and salary liabilities, payroll withholdings, and other accounts payable. It should also include any deferred revenue as well as accrued interest on borrowing for purchasing or improving real estate or other fixed assets such as vehicles.
A32: 2.19 | B32: Managed Funds | C32: This account includes funds for which no set repayment date exists, such as subsidized loans from public agencies (e.g. District Assemblies) or related companies.
A33: 2.20 | B33: Total Liabilities | D33: =D26+D29+D30+D31+D32 -> 0
B34: Equity
A35: 2.21 | B35: Paid-up Capital/Contributed Capital | C35: The value of capital paid by shareholders or members/owners net of any shares repurchased or capital repaid or drawings by owners (in the case of individual operators).
A36: 2.22 | B36: Drawings | C36: The value of cash withdrawals taken out of the business by propritors/Proprietries. (This figure should be negative)
A37: 2.23 | B37: Donated Equity | C37: The total value of all Donations received and recognized as revenue.
A38: 2.24 | B38: Statutory Reserves | C38: Reserves such as those imposed by law, statute, or Regulation
A39: 2.25 | B39: Income Surplus (Prior Period) | C39: The total value of Net Income (After Taxes and Before Donations) from prior periods, net of any dividends paid to shareholders or members.
A40: 2.26 | B40: Current Period P& L | C40: The total value of Net Income (After Taxes and Before Donations) from current period | D40: ='Profit & Loss Statement'!D39 -> 0
A41: 2.27 | B41: Other Reserves | C41: Any other reserves set aside for special purposes
...

Sheet Portfolio Report
A1: ='Profit & Loss Statement'!A1:D1 -> MICRO – CREDIT ASSOCIATION GHANA | E1: =SUM(D4:D10) + IF(E13=E27,0,1) + IF(E13=E51,0,1) + IF(H27>=G27,0,1) -> 6 | F1: =IF(SUM(D4:D9)>0, "Error!", IF(E27<>E13, "Error!", IF(E51<>E13,"Error!", ""))) -> Error!
A2: ='Profit & Loss Statement'!A2:D2 -> MEMBERS REPORTING TEMPLATE
B4: MEMBER NAME: | C4: =IF('Profit & Loss Statement'!C4 = "", "", 'Profit & Loss Statement'!C4) | D4: =IF(C4="",1,IF(ISTEXT(C4),0,1))+IF(OR(ISNUMBER(LEFT(C4)),LEFT(C4)=" "),1,0) -> 1
B5: MEMBER CODE: | C5: =IF('Profit & Loss Statement'!C5 = "", "", 'Profit & Loss Statement'!C5) | D5: =IF(C5="",1,IF(ISTEXT(C5),0,1))+IF(OR(ISNUMBER(LEFT(C5)),LEFT(C5)=" "),1,0) -> 1
B6: RETURN CODE: | C6: =IF('Profit & Loss Statement'!C6 = "", "", 'Profit & Loss Statement'!C6) -> MCAG-PR-UA | D6: =IF(C6="",1,IF(ISTEXT(C6),0,1)) -> 0
B7: REPORTING PERIOD | C7: =IF('Profit & Loss Statement'!C7 = "", "", 'Profit & Loss Statement'!C7) | D7: =IF(C7="",1,IF(ISTEXT(C7),0,1)) -> 1
B8: REPORTING DATE | C8: =IF('Profit & Loss Statement'!C8 = "", "", 'Profit & Loss Statement'!C8) | D8: =IF(C8="",1, 0) -> 1
B9: YEAR | C9: ='Profit & Loss Statement'!C9 | D9: =IF(C9="",1, 0) -> 1
B10: REGION | C10: =IF('Cover Sheet'!C10="", "", 'Cover Sheet'!C10) | D10: =IF(C10="",1, 0) -> 1
A11: 3.0 | B11: Portfolio Activity, Quality and Aging | D11: NUMBER | E11: VALUE (GHS)
A12: 3.1 | B12: Loans Disbursed | C12: The number and Value of all loans disbursed during the period. For MLs using a group lending methodology, the number of loans should refer to the number of individuals receiving loans as part of a group or as part of a group loan. If one person receives more than one loan in the period, count each loan. | D12: ='Regional Breakdown '!D14 -> 0 | E12: =ROUND(('Regional Breakdown '!E14),2) -> 0
A13: 3.2 | B13: Loans outstanding | C13: The number and Principal Value of loans in the Gross Loan Portfolio. For MLs using a group lending methodology, the number of loans should refer to the number of individuals receiving loans as part of a group or as part of a group loan. This includes current, delinquent, and renegotiated loans, but not loans that have been written off. It does not include interest receivable. Loans to employees, board members, or others associated with the institution should be included. | D13: ='Regional Breakdown '!D15 -> 0 | E13: =ROUND(('Balance Sheet'!D16),2) -> 0
A14: 3.3 | B14: Loans written off | C14: The number and Principal Value of loans that have been recognized as uncollectible for accounting purposes. A write-off is an accounting procedure that removes the outstanding balance of the loan from the Gross Loan Portfolio and Impairment Loss Allowance. | D14: ='Regional Breakdown '!D16 -> 0 | E14: ='Regional Breakdown '!E16 -> 0
A15: 3.4 | B15: Top ten (10) largest loans (GHS) | C15: Total Outstanding Principal amount of the 10 largest loans
B16: Portfolio Aging Analysis & Loan Loss Provisioning | D16: NUMBER | E16: VALUE (GHS) | F16: Min Prov Rate (%) | G16: Min Required Prov (GHS) | H16: Actual Prov (GHS)
A17: 3.5 | B17: CURRENT | C17: Principal outstanding of all loans with at least one installments due (Principal and interest) fully paid but excluding rescheduled loans.. | D17: ='Regional Breakdown '!D18 -> 0 | E17: ='Regional Breakdown '!E18 -> 0 | F17: 0.01 | G17: =ROUND(E17*F17,2) -> 0
A18: 3.6 | B18: 1-30 DAYS | C18: Sum of principal outstanding of all loans with at least one installment due in arrears between 1 and 30 days) but excluding rescheduled loans. | D18: ='Regional Breakdown '!D19 -> 0 | E18: ='Regional Breakdown '!E19 -> 0 | F18: 0.05 | G18: =ROUND(E18*F18,2) -> 0
A19: 3.7 | B19: 31-60 DAYS | C19: Sum of principal outstanding of all loans with at least one installment due in arrears between 1 and 30 days) but excluding rescheduled loans. | D19: ='Regional Breakdown '!D20 -> 0 | E19: ='Regional Breakdown '!E20 -> 0 | F19: 0.2 | G19: =ROUND(E19*F19,2) -> 0
A20: 3.8 | B20: 61 - 90 DAYS | C20: Sum of principal outstanding of all loans with at least one installment due in arrears between 61 and 90 days) but excluding rescheduled loans. | D20: ='Regional Breakdown '!D21 -> 0 | E20: ='Regional Breakdown '!E21 -> 0 | F20: 0.4 | G20: =ROUND(E20*F20, 2) -> 0
A21: 3.9 | B21: 91 - 120 DAYS | C21: Sum of principal outstanding of all loans with at least one installment due in arrears between 91 and 120 days) but excluding rescheduled loans. | D21: ='Regional Breakdown '!D22 -> 0 | E21: ='Regional Breakdown '!E22 -> 0 | F21: 0.6 | G21: =ROUND(E21*F21, 2) -> 0
A22: 3.10 | B22: 121 - 150DAYS | C22: Sum of principal outstanding of all loans with at least one installment due in arrears between 121 and 150 days) but excluding rescheduled loans. | D22: ='Regional Breakdown '!D23 -> 0 | E22: ='Regional Breakdown '!E23 -> 0 | F22: 0.8 | G22: =ROUND(E22*F22,2) -> 0
A23: 3.11 | B23: 151 -180 DAYS | C23: Sum of principal outstanding of all loans with at least one installment due in arrears between 151 and 180 days) but excluding rescheduled loans. | D23: ='Regional Breakdown '!D24 -> 0 | E23: ='Regional Breakdown '!E24 -> 0 | F23: 1 | G23: =ROUND(E23*F23,2) -> 0
A24: 3.12 | B24: 181-365 days | C24: Sum of principal outstanding of all loans with at least one installment due in arrears between 181 and 365 days) but excluding rescheduled loans. | D24: ='Regional Breakdown '!D25 -> 0 | E24: ='Regional Breakdown '!E25 -> 0 | F24: 1 | G24: =ROUND(E24*F24,2) -> 0
A25: 3.13 | B25: >365 days | C25: Sum of principal outstanding of all loans with at least one installment due in arrears more than days) but excluding rescheduled loans. | D25: ='Regional Breakdown '!D26 -> 0 | E25: ='Regional Breakdown '!E26 -> 0 | F25: 1 | G25: =ROUND(E25*F25,2) -> 0
A26: 3.14 | B26: Rescheduled (no current arrears) | C26: Principal outstanding of all loans with at least one installment in arrears that have been rescheduled or restructured | D26: ='Regional Breakdown '!D27 -> 0 | E26: ='Regional Breakdown '!E27 -> 0 | F26: 1 | G26: =ROUND(E26*F26,2) -> 0
A27: 3.15 | B27: Total Gross Portfolio | D27: =SUM(D17:D26) -> 0 | E27: =ROUND(SUM(E17:E26),2) -> 0 | F27: =IF(E27=E13," ","Error!") | G27: =ROUND(SUM(G17:G26),2) -> 0 | H27: =ROUND(SUM(H17:H26),2) -> 0 | I27: =IF(H27>=G27," ","Error!")
A28: 3.16 | B28: Total PAR=> 1 day (PAR1 excluding rescheduled) - GHS | C28: Sum of principal outstanding of all loans with at least one installment in arrears for 1 day or more but excluding rescheduled loans) | D28: =SUM(D18:D25) -> 0 | E28: =SUM(E18:E25) -> 0
A29: 3.17 | B29: Total PAR=> 1 day (PAR1 excluding rescheduled) - % | C29: Sum of principal outstanding of all loans with at least one installment in arrears for 1 day or more but excluding rescheduled loans) divided by gross loans outstanding | E29: =IFERROR(E28/E13, 0) -> 0
A30: 3.18 | B30: Total PAR> 30 days (PAR30 excluding rescheduled) - GHS | C30: Sum of principal outstanding of all loans with at least one installment due in arrears for more than 30 days but excluding rescheduled loans) | D30: =SUM(D19:D25) -> 0 | E30: =SUM(E19:E25) -> 0
A31: 3.19 | B31: Total PAR> 30 days (PAR30 excluding rescheduled) - % | C31: Sum of principal outstanding of all loans with at least one installment due in arrears for more than 30 days but excluding rescheduled loans) divided by gross loans outstanding | E31: =IFERROR(E30/E13, 0) -> 0
A32: 3.20 | B32: Total Delinquent Loans (PAR=> 1+Rescheduled) - GHS | C32: Sum of principal outstanding of all loans with at least one installment in arrears for 1 day or more plus rescheduled loans) | D32: =SUM(D18:D26) -> 0 | E32: =SUM(E18:E26) -> 0
A33: 3.21 | B33: Total Delinquent Loans (PAR=> 1+Rescheduled) - % | C33: Sum of principal outstanding of all loans with at least one installment in arrears for 1 day or more plus rescheduled loans) divided by gross loans outstanding | E33: =IFERROR(E32/E13, 0) -> 0
A34: 3.22 | B34: PAR> 30 (PAR> 30+Rescheduled) - GHS | C34: Sum of principal outstanding of all loans with at least one installment due in arrears for more than 30 days plus rescheduled loans) | D34: =SUM(D19:D26) -> 0 | E34: =SUM(E19:E26) -> 0
A35: 3.23 | B35: PAR> 30 (PAR> 30+Rescheduled) - % | C35: Sum of principal outstanding of all loans with at least one installment due in arrears for more than 30 days plus rescheduled loans) divided by gross loans outstanding | E35: =IFERROR(E34/E13, 0) -> 0
A37: 4.0 | B37: SECTORIAL BREAKDOWN OF LOAN PORTFOLIO | D37: NUMBER | E37: VALUE (GHS)
A38: 4.1 | B38: Agric / fishing/ forestry | C38: Breakdown of loans to the Agric/Fishing/Forestry Industry | D38: ='Regional Breakdown '!D39 -> 0 | E38: ='Regional Breakdown '!E39 -> 0
A39: 4.2 | B39: Manufacturing /Agro-processing | C39: Breakdown of loans to the Manufacturing Industry | D39: ='Regional Breakdown '!D40 -> 0 | E39: ='Regional Breakdown '!E40 -> 0
A40: 4.3 | B40: Commerce/Trading | C40: Breakdown of loans for Trading | D40: ='Regional Breakdown '!D41 -> 0 | E40: ='Regional Breakdown '!E41 -> 0
A41: 4.4 | B41: Education | C41: Breakdown of loans to the Education Industry | D41: ='Regional Breakdown '!D42 -> 0 | E41: ='Regional Breakdown '!E42 -> 0
A42: 4.5 | B42: Church / Religious related enterprise | C42: Breakdown of loans to Churches and Religious groups | D42: ='Regional Breakdown '!D43 -> 0 | E42: ='Regional Breakdown '!E43 -> 0
...

Sheet Outreach & Social Performance
A1: ='Profit & Loss Statement'!A1:D1 -> MICRO – CREDIT ASSOCIATION GHANA | E1: =SUM(D4:D10) -> 6 | F1: =IF(SUM(D4:D9)=0,"", "Error!") -> Error!
A2: ='Profit & Loss Statement'!A2:D2 -> MEMBERS REPORTING TEMPLATE
B4: MEMBER NAME: | C4: =IF('Profit & Loss Statement'!C4 = "", "", 'Profit & Loss Statement'!C4) | D4: =IF(C4="",1,IF(ISTEXT(C4),0,1))+IF(OR(ISNUMBER(LEFT(C4)),LEFT(C4)=" "),1,0) -> 1
B5: MEMBER CODE: | C5: =IF('Profit & Loss Statement'!C5 = "", "", 'Profit & Loss Statement'!C5) | D5: =IF(C5="",1,IF(ISTEXT(C5),0,1))+IF(OR(ISNUMBER(LEFT(C5)),LEFT(C5)=" "),1,0) -> 1
B6: RETURN CODE: | C6: =IF('Profit & Loss Statement'!C6 = "", "", 'Profit & Loss Statement'!C6) -> MCAG-PR-UA | D6: =IF(C6="",1,IF(ISTEXT(C6),0,1)) -> 0
B7: REPORTING PERIOD | C7: =IF('Profit & Loss Statement'!C7 = "", "", 'Profit & Loss Statement'!C7) | D7: =IF(C7="",1,IF(ISTEXT(C7),0,1)) -> 1
B8: REPORTING DATE | C8: =IF('Profit & Loss Statement'!C8 = "", "", 'Profit & Loss Statement'!C8) | D8: =IF(C8="",1, 0) -> 1
B9: YEAR | C9: ='Profit & Loss Statement'!C9 | D9: =IF(C9="",1, 0) -> 1
B10: REGION | C10: =IF('Cover Sheet'!C10="", "", 'Cover Sheet'!C10) | D10: =IF(C10="",1, 0) -> 1
A11: 5.0 | B11: OUTREACH & SOCIAL PERFORMANCE DATA
A12: 5.1 | B12: Number of New clients Registered
A13: 5.2 | B13: Number of New Female Clients Registered
A14: 5.3 | B14: Number of New Borrowers
A15: 5.4 | B15: Number of New Female Borrowers
A16: 5.5 | B16: Number of Clients | C16: The number of borrowers, client investors, and other clients who are currently accessing any of the MFI’s financial services; i.e., they have a loan and/or investment account as of the report date. Individuals who access multiple services with an MFI should be counted as a single client. | D16: ='Regional Breakdown '!D55 -> 0
A17: 5.6 | B17: Number of female Clients | C17: The number of female borrowers, client investors, and other female clients who are currently accessing any of the MFI’s financial services; i.e., they have a loan and/ or investment account as of the report date. Individuals who access multiple services with an MFI should be counted as a single client. | D17: ='Regional Breakdown '!D56 -> 0
A18: 5.7 | B18: Number of Active Borrowers | C18: Refers to the number of borrowers with a loan that have neither been fully repaid nor written-off during the reporting period. Borrowers, who have repaid their loan in full, are not considered in this number. | D18: ='Regional Breakdown '!D57 -> 0
A19: 5.8 | B19: Number of Active Female Borrowers | C19: Refers to the number of female borrowers with a loan that have neither been fully repaid nor written-off during the reporting period. Female borrowers, who have repaid their loan in full, are not considered in this number. | D19: ='Regional Breakdown '!D58 -> 0
A20: 5.9 | B20: Value of compulsory savings (GHS) | D20: ='Balance Sheet'!D26 -> 0
A21: 5.10 | B21: Average loan size disbursed (GHS) | D21: =IFERROR('Portfolio Report'!E12/'Portfolio Report'!D12, 0) -> 0
A22: 5.11 | B22: Average loan size outstanding (GHS) | D22: =IFERROR('Portfolio Report'!E13/'Portfolio Report'!D13, 0) -> 0
A23: 5.12 | B23: Value of Client Investments (GHS) | C23: Funds placed with/ lent money to the institution by clients for a fixed period | D23: ='Regional Breakdown '!D61 -> 0
A24: 5.13 | B24: Number of client investors | C24: This refers to the clients who have placed funds with/ lent money to the institution for a fixed period | D24: ='Regional Breakdown '!D62 -> 0
A25: 5.14 | B25: Number of female client investors | C25: This refers to the female clients who have placed funds with/ lent money to the institution for a fixed period | D25: ='Regional Breakdown '!D63 -> 0
A26: 5.15 | B26: Value of Loans to Women | C26: Amount of loans disbursed to women during the reporting period | D26: ='Regional Breakdown '!D66 -> 0
B27: Details about Staff
A28: 5.16 | B28: Number of Personnel (Staff)
A29: 5.17 | B29: Number of female Personnel (Staff)
A30: 5.18 | B30: Number of Loan Officers/Credit Officers
A31: 5.19 | B31: Number of new staff recruited during the period
A32: 5.20 | B32: Number of staff who resigned during the period
B33: Details about Management Staff
A34: 5.21 | B34: Number of Staff in Management position
A35: 5.22 | B35: Number of Female Staff in management position
A36: 5.23 | B36: Number of management meetings held during the period
A37: 5.24 | B37: Number of Advisory committee members
A38: 5.25 | B38: Number of Advisory committee meetings held during the period
B39: Support to Start-ups, Youth and Disabled
A40: 5.26 | B40: Number of start-up businesses supported with credit during the period
A41: 5.27 | B41: Number of enterprises that received credit during the period
...

Sheet Regional Breakdown 
A1: ='Profit & Loss Statement'!A1:D1 -> MICRO – CREDIT ASSOCIATION GHANA | E1: =SUM(D4:D10) + IF(D15=D28,0,1) + IF(D15=D57,0,1) + IF(D15=D52,0,1) + IF(E15=E28,0,1) + IF(E15=E52,0,1) -> 6 | F1: Errors
A2: ='Profit & Loss Statement'!A2:D2 -> MEMBERS REPORTING TEMPLATE
B4: MEMBER NAME: | C4: =IF('Profit & Loss Statement'!C4 = "", "", 'Profit & Loss Statement'!C4) | D4: =IF(C4="",1,IF(ISTEXT(C4),0,1))+IF(OR(ISNUMBER(LEFT(C4)),LEFT(C4)=" "),1,0) -> 1
B5: MEMBER CODE: | C5: =IF('Profit & Loss Statement'!C5 = "", "", 'Profit & Loss Statement'!C5) | D5: =IF(C5="",1,IF(ISTEXT(C5),0,1))+IF(OR(ISNUMBER(LEFT(C5)),LEFT(C5)=" "),1,0) -> 1
B6: RETURN CODE: | C6: =IF('Profit & Loss Statement'!C6 = "", "", 'Profit & Loss Statement'!C6) -> MCAG-PR-UA | D6: =IF(C6="",1,IF(ISTEXT(C6),0,1)) -> 0
B7: REPORTING PERIOD | C7: =IF('Profit & Loss Statement'!C7 = "", "", 'Profit & Loss Statement'!C7) | D7: =IF(C7="",1,IF(ISTEXT(C7),0,1)) -> 1
B8: REPORTING DATE | C8: =IF('Profit & Loss Statement'!C8 = "", "", 'Profit & Loss Statement'!C8) | D8: =IF(C8="",1, 0) -> 1
B9: YEAR | C9: ='Profit & Loss Statement'!C9 | D9: =IF(C9="",1, 0) -> 1
B10: REGION | C10: =IF('Profit & Loss Statement'!C10 = "", "", 'Profit & Loss Statement'!C10) | D10: =IF(C10="",1, 0) -> 1
F11: REGIONAL BREAK DOWN
B12: PARAMETERS/ INDICATORS | C12: DESCRIPTION | D12: TOTAL | F12: =RIGHT(C10,2)
A13: 1.0 | B13: PORTFOLIO ACTIVITY, QUALITY AND AGING | C13: DEFINITION | D13: NUMBER | E13: VALUE (GHS) | F13: NUMBER | G13: VALUE (GHS)
A14: 1.1 | B14: Loans Disbursed | C14: The number and Value of all loans disbursed during the period. For MFIs using a group lending methodology, the number of loans should refer to the number of individuals receiving loans as part of a group or as part of a group loan. If one person receives more than one loan in the period, count each loan. | D14: =F14 -> 0 | E14: =ROUND((G14),2) -> 0
A15: 1.2 | B15: Loans Outstanding | C15: The number and Principal Value of loans in the Gross Loan Portfolio. For MFIs using a group lending methodology, the number of loans should refer to the number of individuals receiving loans as part of a group or as part of a group loan. | D15: =F15 -> 0 | E15: =ROUND((G15),2) -> 0 | H15: =IF(D15<>D28,"Error!", IF(D15<>D52, "Error!", ""))
A16: 1.3 | B16: Loans written off during the period | C16: The number and Principal Value of loans that have been recognized as uncollectible for accounting purposes. A write-off is an accounting procedure that removes the outstanding balance of the loan from the Gross Loan Portfolio and Impairment Loss Allowance. | D16: =F16 -> 0 | E16: =ROUND((G16),2) -> 0
B17: Aging of Loans:
A18: 1.4 | B18: CURRENT | C18: Principal outstanding of all loans with at least one installment due (Principal and interest) fully paid but excluding rescheduled loans.. | D18: =F18 -> 0 | E18: =G18 -> 0
A19: 1.5 | B19: 1-30 DAYS | C19: Sum of principal outstanding of all loans with at least one installment due in arrears between 1 and 30 days) but excluding rescheduled loans. | D19: =F19 -> 0 | E19: =G19 -> 0
A20: 1.6 | B20: 31-60 DAYS | C20: Sum of principal outstanding of all loans with at least one installment due in arrears between 1 and 30 days) but excluding rescheduled loans. | D20: =F20 -> 0 | E20: =G20 -> 0
A21: 1.7 | B21: 61 - 90 DAYS | C21: Sum of principal outstanding of all loans with at least one installment due in arrears between 61 and 90 days) but excluding rescheduled loans. | D21: =F21 -> 0 | E21: =G21 -> 0
A22: 1.8 | B22: 91 - 120 DAYS | C22: Sum of principal outstanding of all loans with at least one installment due in arrears between 91 and 120 days) but excluding rescheduled loans. | D22: =F22 -> 0 | E22: =G22 -> 0
A23: 1.9 | B23: 121 - 150DAYS | C23: Sum of principal outstanding of all loans with at least one installment due in arrears between 121 and 150 days) but excluding rescheduled loans. | D23: =F23 -> 0 | E23: =G23 -> 0
A24: 1.10 | B24: 151 -180 DAYS | C24: Sum of principal outstanding of all loans with at least one installment due in arrears between 151 and 180 days) but excluding rescheduled loans. | D24: =F24 -> 0 | E24: =G24 -> 0
A25: 1.11 | B25: 181-365 days | C25: Sum of principal outstanding of all loans with at least one installment due in arrears between 181 and 365 days) but excluding rescheduled loans. | D25: =F25 -> 0 | E25: =G25 -> 0
A26: 1.12 | B26: >365 days | C26: Sum of principal outstanding of all loans with at least one installment due in arrears more than days) but excluding rescheduled loans. | D26: =F26 -> 0 | E26: =G26 -> 0
A27: 1.13 | B27: Rescheduled (no current arrears) | C27: Principal outstanding of all loans with at least one installment in arrears that have been rescheduled or restructured | D27: =F27 -> 0 | E27: =G27 -> 0
A28: 1.14 | B28: Total Gross Loans Outstanding | D28: =SUM(D18:D27) -> 0 | E28: =ROUND(SUM(E18:E27),2) -> 0 | F28: =SUM(F18:F27) -> 0 | G28: =SUM(G18:G27) -> 0 | H28: =IF(E15<>E28,"Error!", IF(E15<>E52, "Error!", ""))
A29: 1.15 | B29: Total PAR=> 1 day (PAR1 excluding rescheduled) (GHS) | C29: Sum of principal outstanding of all loans with at least one installment in arrears for 1 day or more but excluding rescheduled loans) | D29: =SUM(D19:D26) -> 0 | E29: =SUM(E19:E26) -> 0 | F29: =SUM(F19:F26) -> 0 | G29: =SUM(G19:G26) -> 0
A30: 1.16 | B30: Total PAR=> 1 day (PAR1 excluding rescheduled) % | C30: Sum of principal outstanding of all loans with at least one installment in arrears for 1 day or more but excluding rescheduled loans) | E30: =IFERROR(SUM(E19:E26)/E15,0) -> 0 | G30: =IFERROR(SUM(G19:G26)/G15, 0) -> 0
A31: 1.17 | B31: Total PAR> 30 days (PAR30 excluding rescheduled)(GHS) | C31: Sum of principal outstanding of all loans with at least one installment due in arrears for more than 30 days but excluding rescheduled loans) | D31: =SUM(D20:D26) -> 0 | E31: =SUM(E20:E26) -> 0 | F31: =SUM(F20:F26) -> 0 | G31: =SUM(G20:G26) -> 0
A32: 1.18 | B32: Total PAR> 30 days (PAR30 excluding rescheduled) % | C32: Sum of principal outstanding of all loans with at least one installment due in arrears for more than 30 days but excluding rescheduled loans) | E32: =IFERROR(SUM(E20:E26)/E15, 0) -> 0 | G32: =IFERROR(SUM(G20:G26)/G15, 0) -> 0
A33: 1.19 | B33: Total Delinquent Loans (PAR=> 1+Rescheduled) (GHS) | C33: Sum of principal outstanding of all loans with at least one installment in arrears for 1 day or more plus rescheduled loans) | D33: =SUM(D19:D27) -> 0 | E33: =SUM(E19:E27) -> 0 | F33: =SUM(F19:F27) -> 0 | G33: =SUM(G19:G27) -> 0
A34: 1.20 | B34: Total Delinquent Loans (PAR=> 1+Rescheduled) % | C34: Sum of principal outstanding of all loans with at least one installment in arrears for 1 day or more plus rescheduled loans) | E34: =IFERROR(SUM(E19:E27)/E15, 0) -> 0 | G34: =IFERROR(SUM(G19:G27)/G15, 0) -> 0
A35: 1.21 | B35: PAR> 30 (PAR> 30+Rescheduled) (GHS) | C35: Sum of principal outstanding of all loans with at least one installment due in arrears for more than 30 days plus rescheduled loans) | D35: =SUM(D20:D27) -> 0 | E35: =SUM(E20:E27) -> 0 | F35: =SUM(F20:F27) -> 0 | G35: =SUM(G20:G27) -> 0
A36: 1.22 | B36: PAR> 30 (PAR> 30+Rescheduled) % | C36: Sum of principal outstanding of all loans with at least one installment due in arrears for more than 30 days plus rescheduled loans) | E36: =IFERROR(SUM(E20:E27)/E15, "") | G36: =IFERROR(SUM(G20:G27)/G15, 0) -> 0
A38: 2.0 | B38: SECTORIAL BREAKDOWN OF LOAN PORTFOLIO | D38: NUMBER | E38: VALUE (GHS) | F38: NUMBER | G38: VALUE (GHS)
A39: 2.1 | B39: Agric / fishing/ forestry | C39: Breakdown of loans to the Agric / Fishing/Forestry Industry | D39: =F39 -> 0 | E39: =G39 -> 0
A40: 2.2 | B40: Manufacturing /Agro-processing | C40: Breakdown of loans to the Manufacturing Industry | D40: =F40 -> 0 | E40: =G40 -> 0
A41: 2.3 | B41: Commerce/Trading | C41: Breakdown of loans for Trading | D41: =F41 -> 0 | E41: =G41 -> 0
A42: 2.4 | B42: Education | C42: Breakdown of loans to the Education Industry | D42: =F42 -> 0 | E42: =G42 -> 0
...

Sheet Ratios
A2: NO. | B2: PARAMETER/ INDICATOR | C2: Definition/ formula for the ratio | D2: Source Data | E2: Calculated Ratios
B3: PROFITABILITY & SUSTAINABILITY
A4: PS1 | B4: Return on Assets | C4: Net Operating income after taxes Average Assets | D4: P&L line 1.25/Balance sheet line 2.34 | E4: =IFERROR('Profit & Loss Statement'!D39/'Balance Sheet'!D46, 0) -> 0
A5: PS2 | B5: Return on Equity | C5: Net Operating income after taxes Average Equity | D5: P&L line 1.25/Balance sheet line 2.36 | E5: =IFERROR('Profit & Loss Statement'!D39/'Balance Sheet'!D48, 0) -> 0
A6: PS3 | B6: Operational Sustainability (OSS) expressed as percentage | C6: Operating Income Financing Costs + Loan Loss Provisions + Operating Costs | D6: (P&L line 1.6/(P&L line 1.12+1.14+1.19) | E6: =IFERROR('Profit & Loss Statement'!D18/('Profit & Loss Statement'!D25+'Profit & Loss Statement'!D27+'Profit & Loss Statement'!D33),0) -> 0
A7: PS4 | B7: Financial Self-Sufficiency (FSS) expressed as percentage | C7: Adjusted Financial Revenue (Adjusted Financial Expense + Adjusted Impairment Losses on Loans + Adjusted Operating Expense) | D7: (P&L line 1.30/(P&L lines 1.29+1.28+1.27)) | E7: =IFERROR('Profit & Loss Statement'!D46/('Profit & Loss Statement'!D45+'Profit & Loss Statement'!D44+'Profit & Loss Statement'!D43),0) -> 0
A8: PS5 | B8: Net Profit Margin | C8: Net income after tax Total Revenue | D8: P & L line 1.25/(P & L line 1.6 + P & L line 1.21) | E8: =IFERROR('Profit & Loss Statement'!D39/('Profit & Loss Statement'!D18+'Profit & Loss Statement'!D35),0) -> 0
A9: PS6 | B9: Net Interest margin | C9: Net Interest Income Average Earning assets | D9: P& L line 1.13/ Balance sheet line2.41 | E9: =IFERROR('Profit & Loss Statement'!D26/'Balance Sheet'!D53,0) -> 0
A10: PS7 | B10: Financial Expense Ratio | C10: Interest and Fees on Funding liabilities Average Gross Loan Portfolio | D10: [P & L line 1.12-P & L line1.11]/ [Balance sheet line 2.35 | E10: =IFERROR(('Profit & Loss Statement'!D25-'Profit & Loss Statement'!D24)/'Balance Sheet'!D16,0) -> 0
B11: ASSETS/ LIABILITY MANAGEMENT & FINANCIAL STRUCTURE
A12: FS1 | B12: Total Asset | D12: Balance sheet line 2.12 | E12: ='Balance Sheet'!D24 -> 0
A13: FS2 | B13: Capital to Assets Ratio | C13: Total Equity Total Assets | D13: Balance Sheet line 2.27/ Balance sheet line 2.12 | E13: =IFERROR('Balance Sheet'!D42/'Balance Sheet'!D24,0) -> 0
A14: FS3 | B14: Gross Loan Portfolio to Total Assets Ratio | C14: Value of Gross Loan Portfolio Total Asset | D14: Balance sheet line 2.4/ Balance sheet line 2.12 | E14: =IFERROR('Balance Sheet'!D16/'Balance Sheet'!D24,0) -> 0
A15: FS4 | B15: Debt to Equity Ratio | C15: Total Liabilities Total Equity | D15: Balance sheet line 2.20/ Balance sheet line 2.27 | E15: =IFERROR('Balance Sheet'!D33/'Balance Sheet'!D42,0) -> 0
A16: FS6 | B16: Yield on Gross Portfolio | C16: Cash Received from Interest, Fees, and Commissions on Loan Portfolio Average Gross Loan Portfolio | D16: P&L line (1.1+1.2)/[Balance sheet line 2.35 | E16: =IFERROR(('Profit & Loss Statement'!D13+'Profit & Loss Statement'!D14)/'Balance Sheet'!D16,0) -> 0
A17: FS8 | B17: Yield on Investments | C17: Cash Received from Interest, Fees, and Commissions on Investments Average Investments | D17: P&L line (1.3+1.4)/Balance sheet line2.37 | E17: =IFERROR(('Profit & Loss Statement'!D15+'Profit & Loss Statement'!D16)/'Balance Sheet'!D49,0) -> 0
A18: FS10 | B18: Cost of Funds Ratio* | C18: Financial Expenses on Funding Liabilities/Average Deposit + Average Borrowings) | D18: (P&L line 1.12- P&L 1.11 )/ (Balance sheet line 2.38 +2.39) | E18: =IFERROR(('Profit & Loss Statement'!D25-'Profit & Loss Statement'!D24)/('Balance Sheet'!D50+'Balance Sheet'!D51),0) -> 0
A19: FS11 | B19: Liquid Ratio | C19: (Cash +Trade Investments)/Security Deposit +Short-term Borrowings+Interest Payable on Funding Liabilities +Accounts Payable and Other Short-term Liabilities | D19: Balance sheet line (2.1+2.2+2.3) / Balance sheet line (2.13+2.14+2.17+2.18) | E19: =IFERROR(('Balance Sheet'!D13+'Balance Sheet'!D14+'Balance Sheet'!D15)/('Balance Sheet'!D26+'Balance Sheet'!D27+'Balance Sheet'!D30+'Balance Sheet'!D31),0) -> 0
A20: FS12 | B20: Uncovered Capital Ratio (portfolio Quality & Vulnerability) | C20: PAR>30 - impairment Allowance Total Equity | D20: [Portfolio report line 3.22 column E - Balance Sheet line 2.5] / Balance sheet line2.27 | E20: =IFERROR('Portfolio Report'!E34/'Balance Sheet'!D42,0) -> 0
B21: EFFICIENCY
A22: E1 | B22: Operating Expenses Ratio | C22: Operating Expense Average Gross Loan Portfolio | D22: P&L line 1.19/Balance sheet line 2.35 | E22: =IFERROR('Profit & Loss Statement'!D33/'Balance Sheet'!D47,0) -> 0
A23: E2 | B23: Personnel Expense Ratio | C23: Personnel Expense Average Gross Loan Portfolio | D23: P&L line 1.16/Balance sheet line 2.35 | E23: =IFERROR('Profit & Loss Statement'!D30/'Balance Sheet'!D47,0) -> 0
A24: E3 | B24: Administrative Expense Ratio | C24: Administrative Expense Average Gross Loan Portfolio | D24: P&L line (1.17+1.18)/ Balance sheet line 2.35 | E24: =IFERROR(('Profit & Loss Statement'!D31+'Profit & Loss Statement'!D32)/'Balance Sheet'!D47,0) -> 0
A25: E4 | B25: Cost Income Ratio | C25: Operating Expense Total Revenue | D25: P&L line 1.19/ (P&L line 1.6+ P & L line 2.1) | E25: =IFERROR('Profit & Loss Statement'!D33/'Profit & Loss Statement'!D18,0) -> 0
A26: E5 | B26: Cost per Borrower | C26: Operating expense Average number of active borrowers | D26: P&L line 1.19/Balance sheet line 2.40 | E26: =IFERROR('Profit & Loss Statement'!D33/'Balance Sheet'!D52,0) -> 0
B27: PRODUCTIVITY
A28: P1 | B28: Borrowers per Loans Officer | C28: Number of active borrowers Number of loan officers | D28: outreach & social performance line 5.7/ outreach & social performance line 5.18 | E28: =IFERROR('Outreach & Social Performance'!D18/'Outreach & Social Performance'!D30,0) -> 0
A29: P2 | B29: Borrowers per Staff | C29: Number of active borrowers Number of staff | D29: outreach & social performance line 5.7/ outreach & social performance line 5.17 | E29: =IFERROR('Outreach & Social Performance'!D18/'Outreach & Social Performance'!D28,0) -> 0
A30: P3 | B30: Personnel Allocation (loan officers as a share of total staff) | C30: Number of loan officers Total Number of staff | D30: outreach & social performance line 5.18 /outreach & social performance line 5.17 | E30: =IFERROR('Outreach & Social Performance'!D30/'Outreach & Social Performance'!D28,0) -> 0
B31: PORTFOLIO QUALITY
A32: PQ1 | B32: Gross Loan Portfolio | C32: Sum of Principal Outstanding of All Loans | D32: Balance sheet line 2.4 | E32: ='Balance Sheet'!D16 -> 0
A33: PQ2 | B33: Portfolio at Risk > 30 days. | C33: Value of all Loans with Payments Past Due >30 days + Rescheduled Loans Total Gross Outstanding Loan Portfolio | D33: Portfolio report line 3.22 column E/ Balance sheet line 2.4 | E33: ='Portfolio Report'!E35 -> 0
A34: PQ3 | B34: PAR> 30 days to Equity | C34: Portfolio at Risk>30 days Equity (Capital +Reserves) | D34: Portfolio report line 3.22column E/ Balance sheet line 2.27 | E34: =IFERROR('Portfolio Report'!E34/'Balance Sheet'!D42,0) -> 0
A35: PQ4 | B35: Write-off ratio | C35: Value of Loans Written Off Average Gross Loan Portfolio | D35: Portfolio report line 3.3 column E/Balance sheet line 2.35 | E35: =IFERROR('Portfolio Report'!E14/'Balance Sheet'!D16,0) -> 0
A36: PQ5 | B36: Risk Coverage | C36: Net Profit_____ Value of all loans with Payment past due > 30 days + Value of rescheduled loans | D36: P & L line 1.23/ Portfolio report line 3.22 column E | E36: =IFERROR('Profit & Loss Statement'!D37/'Portfolio Report'!E34,0) -> 0
A37: PQ6 | B37: Value of loans written off during the Period | D37: Portfolio report line 3.3 column E | E37: ='Portfolio Report'!E14 -> 0
A38: PQ7 | B38: Loan Loss Provision Expense Ratio | C38: Loan Loss Provisioning Expenses Period Average Gross Portfolio | D38: P & L line 1.14/ Balance sheet line 2.35 | E38: =IFERROR('Profit & Loss Statement'!D27/'Balance Sheet'!D47,0) -> 0
B39: OUTREACH
A40: O1 | B40: Number of Clients | D40: Outreach & Social Performance line 5.5 | E40: ='Outreach & Social Performance'!D16 -> 0
A41: O5 | B41: Number of Active Borrowers | C41: The number of individuals who have an outstanding loan balance with the MFI during the reporting period | D41: Outreach & Social Performance line 5.7 | E41: ='Outreach & Social Performance'!D18 -> 0
...
